Workbook

Sheet Ene-Jun
B1: CALENDARIO ACTUALIZACIÓN FICHAS 2026 (ENERO-JUNIO) DIRECCIÓN DE ESTUDIOS ECONÓMICOS
A3: DÍA | B3: ENERO | C3: FEBRERO | D3: MARZO | E3: ABRIL | F3: MAYO | G3: JUNIO
A4: 1 | G4: =CONCATENATE(Detalle!$A$13,"."," ",Detalle!$F$13,"."," ",Detalle!$C$13,"."," ",Detalle!$G$13,".") -> Inversión Extranjera Directa hacia México por Entidad. 1T2026. Cifras Revisadas. SE.
A5: 2
A6: 3
A7: 4
A8: 5
A9: 6
A10: 7
A11: 8 | E11: =CONCATENATE(Detalle!$A$21,"."," ",Detalle!$F$21,"."," ","Marzo","."," ",Detalle!$G$21,".") -> Puestos de trabajo y salario por entidad. 2026. Marzo. IMSS. | F11: =CONCATENATE(Detalle!$A$21,"."," ",Detalle!$F$21,"."," ","Abril","."," ",Detalle!$G$21,".") -> Puestos de trabajo y salario por entidad. 2026. Abril. IMSS. | G11: =CONCATENATE("*",Detalle!$A$21,"."," ",Detalle!$F$21,"."," ","Mayo","."," ",Detalle!$G$21,".",CHAR(10),"*",Detalle!$A$13,"."," ",Detalle!$F$13,"."," ",Detalle!$C$13,"."," ",Detalle!$G$13,".") -> *Puestos de trabajo y salario por entidad. 2026. Mayo. IMSS. *Inversión Extranjera Directa hacia México por Entidad. 1T2026. Cifras Revisadas. SE.
A12: 9 | G12: =CONCATENATE(Detalle!$A$13,"."," ",Detalle!$F$13,"."," ",Detalle!$C$13,"."," ",Detalle!$G$13,".") -> Inversión Extranjera Directa hacia México por Entidad. 1T2026. Cifras Revisadas. SE.
A13: 10
A14: 11
A15: 12
A16: 13
A17: 14
A18: 15 | G18: =CONCATENATE(Detalle!A20,"."," ",Detalle!F20,"."," ",Detalle!D20,"."," ",Detalle!G20,".") -> Indicadores de Competitividad. 2026. Anual. IMCO.
A19: 16
A20: 17
A21: 18
A22: 19 | D22: =CONCATENATE(Detalle!$A$12,"."," ",Detalle!$F$12,"."," ",Detalle!$C$12,"."," ",Detalle!$G$12,".") -> Inversión Extranjera Directa hacia México por Entidad. 4T2025. Cifras Revisadas. SE.
A23: 20 | F23: =CONCATENATE("*",Detalle!A16,"."," ",Detalle!F16,"."," ",Detalle!C16,"."," ",Detalle!G16,".",CHAR(10),"*",Detalle!$A$13,"."," ",Detalle!$F$13,"."," ",Detalle!$C$13,"."," ",Detalle!$G$13,".") -> *DENUE. 2025. Cifras Definitivas. INEGI. *Inversión Extranjera Directa hacia México por Entidad. 1T2026. Cifras Revisadas. SE.
A24: 21 | F24: =CONCATENATE(Detalle!$A$13,"."," ",Detalle!$F$13,"."," ",Detalle!$C$13,"."," ",Detalle!$G$13,".") -> Inversión Extranjera Directa hacia México por Entidad. 1T2026. Cifras Revisadas. SE.
A25: 22
A26: 23
A27: 24 | C27: =CONCATENATE(Detalle!A8,"."," ",Detalle!F8,"."," ",Detalle!C8,"."," ",Detalle!G8,".") -> Encuesta Nacional de Ocupación y Empleo. 4T2025. Cifras Definitivas. INEGI.
A28: 25
A29: 26 | F29: =CONCATENATE("*",Detalle!A9,"."," ",Detalle!F9,"."," ",Detalle!C9,"."," ",Detalle!G9,".",CHAR(10),"*",Detalle!$A$13,"."," ",Detalle!$F$13,"."," ",Detalle!$C$13,"."," ",Detalle!$G$13,".") -> *Encuesta Nacional de Ocupación y Empleo. 1T2026. Cifras Definitivas. INEGI. *Inversión Extranjera Directa hacia México por Entidad. 1T2026. Cifras Revisadas. SE.
A30: 27 | F30: =CONCATENATE(Detalle!$A$13,"."," ",Detalle!$F$13,"."," ",Detalle!$C$13,"."," ",Detalle!$G$13,".") -> Inversión Extranjera Directa hacia México por Entidad. 1T2026. Cifras Revisadas. SE.
A31: 28
A32: 29
A33: 30 | G33: =CONCATENATE(Detalle!A5,"."," ",Detalle!F5,"."," ",Detalle!C5,"."," ",Detalle!G5,".") -> Exportaciones por Entidad Federativa. 1T2026. Cifras Preliminares. INEGI.
A34: 31 | D34: =CONCATENATE(Detalle!A4,"."," ",Detalle!F4,"."," ",Detalle!C4,"."," ",Detalle!G4,".") -> Exportaciones por Entidad Federativa. 4T2025. Cifras Preliminares. INEGI.
A37: Etiqueta
A38: PIBE | B38: Producto Interno Bruto por Entidad Federativa
A39: EEF | B39: Exportaciones por Entidad Federativa
A40: ENOE | B40: Encuesta Nacional de Ocupación y Empleo Trimestral
A41: IED | B41: Inversión Extranjera Directa hacia México por Entidad Federativa
A42: DENUE | B42: Directorio Estadístico Nacional de Unidades Económicas
A43: CET | B43: Compendio Estadístico del Turismo en México
...

Sheet Jul-Dic
B1: CALENDARIO ACTUALIZACIÓN FICHAS (JULIO-DICIEMBRE) DIRECCIÓN DE ESTUDIOS ECONÓMICOS
A3: DÍA | B3: JULIO | C3: AGOSTO | D3: SEPTIEMBRE | E3: OCTUBRE | F3: NOVIEMBRE | G3: DICIEMBRE
A4: 1 | D4: =CONCATENATE(Detalle!$A$14,"."," ",Detalle!$F$14,"."," ",Detalle!$C$14,"."," ",Detalle!$G$14,".") -> Inversión Extranjera Directa hacia México por Entidad. 2T2026. Cifras Revisadas. SE. | G4: =CONCATENATE(Detalle!$A$15,"."," ",Detalle!$F$15,"."," ",Detalle!$C$15,"."," ",Detalle!$G$15,".") -> Inversión Extranjera Directa hacia México por Entidad. 3T2026. Cifras Revisadas. SE.
A5: 2
A6: 3
A7: 4
A8: 5
A9: 6 | B9: =CONCATENATE(Detalle!A2,"."," ",Detalle!F2,"."," ",Detalle!C2,"."," ",Detalle!G2,".") -> Producto Interno Bruto por Entidad Federativa. 2024. Cifras Revisadas. INEGI.
A10: 7 | G10: =CONCATENATE("*",Detalle!A3,"."," ",Detalle!F3,"."," ",Detalle!C3,"."," ",Detalle!G3,".",CHAR(10),"*",Detalle!$A$15,"."," ",Detalle!$F$15,"."," ",Detalle!$C$15,"."," ",Detalle!$G$15,".") -> *Producto Interno Bruto por Entidad Federativa. 2025. Cifras Preliminares. INEGI. *Inversión Extranjera Directa hacia México por Entidad. 3T2026. Cifras Revisadas. SE.
A11: 8 | B11: =CONCATENATE(Detalle!$A$21,"."," ",Detalle!$F$21,"."," ","Junio","."," ",Detalle!$G$21,".") -> Puestos de trabajo y salario por entidad. 2026. Junio. IMSS. | D11: =CONCATENATE("*",Detalle!$A$21,"."," ",Detalle!$F$21,"."," ","Agosto","."," ",Detalle!$G$21,".",CHAR(10),"*",Detalle!$A$14,"."," ",Detalle!$F$14,"."," ",Detalle!$C$14,"."," ",Detalle!$G$14,".") -> *Puestos de trabajo y salario por entidad. 2026. Agosto. IMSS. *Inversión Extranjera Directa hacia México por Entidad. 2T2026. Cifras Revisadas. SE. | E11: =CONCATENATE(Detalle!$A$21,"."," ",Detalle!$F$21,"."," ","Septiembre","."," ",Detalle!$G$21,".") -> Puestos de trabajo y salario por entidad. 2026. Septiembre. IMSS. | G11: =CONCATENATE("*",Detalle!$A$21,"."," ",Detalle!$F$21,"."," ","Noviembre","."," ",Detalle!$G$21,".",CHAR(10),"*",Detalle!$A$15,"."," ",Detalle!$F$15,"."," ",Detalle!$C$15,"."," ",Detalle!$G$15,".") -> *Puestos de trabajo y salario por entidad. 2026. Noviembre. IMSS. *Inversión Extranjera Directa hacia México por Entidad. 3T2026. Cifras Revisadas. SE.
A12: 9 | D12: =CONCATENATE(Detalle!$A$14,"."," ",Detalle!$F$14,"."," ",Detalle!$C$14,"."," ",Detalle!$G$14,".") -> Inversión Extranjera Directa hacia México por Entidad. 2T2026. Cifras Revisadas. SE. | F12: =CONCATENATE(Detalle!$A$21,"."," ",Detalle!$F$21,"."," ","Octubre","."," ",Detalle!$G$21,".") -> Puestos de trabajo y salario por entidad. 2026. Octubre. IMSS. | G12: =CONCATENATE(Detalle!$A$15,"."," ",Detalle!$F$15,"."," ",Detalle!$C$15,"."," ",Detalle!$G$15,".") -> Inversión Extranjera Directa hacia México por Entidad. 3T2026. Cifras Revisadas. SE.
A13: 10 | C13: =CONCATENATE(Detalle!$A$21,"."," ",Detalle!$F$21,"."," ","Julio","."," ",Detalle!$G$21,".") -> Puestos de trabajo y salario por entidad. 2026. Julio. IMSS.
A14: 11
A15: 12
A16: 13
A17: 14
A18: 15 | F18: =CONCATENATE("*",Detalle!A18,"."," ",Detalle!F18,"."," ",Detalle!C18,"."," ",Detalle!G18,".", CHAR(10), "*",Detalle!A19,"."," ",Detalle!F19,"."," ",Detalle!C19,"."," ",Detalle!G19,".") -> *Recepción de Turistas. 2025. Cifras Revisadas. DATATUR. *Educación Superior. 2025-2026. Cifras Revisadas. ANUIES.
A19: 16
A20: 17
A21: 18
A22: 19
A23: 20 | C23: =CONCATENATE(Detalle!$A$14,"."," ",Detalle!$F$14,"."," ",Detalle!$C$14,"."," ",Detalle!$G$14,".") -> Inversión Extranjera Directa hacia México por Entidad. 2T2026. Cifras Revisadas. SE. | F23: =CONCATENATE(Detalle!$A$15,"."," ",Detalle!$F$15,"."," ",Detalle!$C$15,"."," ",Detalle!$G$15,".") -> Inversión Extranjera Directa hacia México por Entidad. 3T2026. Cifras Revisadas. SE.
A24: 21
A25: 22
A26: 23 | G26: =CONCATENATE(Detalle!A7,"."," ",Detalle!F7,"."," ",Detalle!C7,"."," ",Detalle!G7,".") -> Exportaciones por Entidad Federativa. 3T2026. Cifras Preliminares. INEGI.
A27: 24
A28: 25 | C28: =CONCATENATE("*",Detalle!A10,"."," ",Detalle!F10,"."," ",Detalle!C10,"."," ",Detalle!G10,".",CHAR(10),"*",Detalle!$A$14,"."," ",Detalle!$F$14,"."," ",Detalle!$C$14,"."," ",Detalle!$G$14,".") -> *Encuesta Nacional de Ocupación y Empleo. 2T2026. Cifras Definitivas. INEGI. *Inversión Extranjera Directa hacia México por Entidad. 2T2026. Cifras Revisadas. SE. | F28: =CONCATENATE("*",Detalle!A11,"."," ",Detalle!F11,"."," ",Detalle!C11,"."," ",Detalle!G11,".", CHAR(10), "*",Detalle!A17,"."," ",Detalle!F17,"."," ",Detalle!C17,"."," ",Detalle!G17,".",CHAR(10),"*",Detalle!$A$15,"."," ",Detalle!$F$15,"."," ",Detalle!$C$15,"."," ",Detalle!$G$15,".") -> *Encuesta Nacional de Ocupación y Empleo. 3T2026. Cifras Definitivas. INEGI. *DENUE. 2025. Cifras Definitivas. INEGI. *Inversión Extranjera Directa hacia México por Entidad. 3T2026. Cifras Revisadas. SE.
A29: 26 | C29: =CONCATENATE(Detalle!$A$14,"."," ",Detalle!$F$14,"."," ",Detalle!$C$14,"."," ",Detalle!$G$14,".") -> Inversión Extranjera Directa hacia México por Entidad. 2T2026. Cifras Revisadas. SE. | F29: =CONCATENATE(Detalle!$A$15,"."," ",Detalle!$F$15,"."," ",Detalle!$C$15,"."," ",Detalle!$G$15,".") -> Inversión Extranjera Directa hacia México por Entidad. 3T2026. Cifras Revisadas. SE.
A30: 27
A31: 28
A32: 29
A33: 30 | D33: =CONCATENATE(Detalle!A6,"."," ",Detalle!F6,"."," ",Detalle!C6,"."," ",Detalle!G6,".") -> Exportaciones por Entidad Federativa. 2T2026. Cifras Preliminares. INEGI.
A34: 31
A37: Etiqueta
A38: PIB | B38: Producto Interno Bruto por Entidad Federativa
A39: EEF | B39: Exportaciones por Entidad Federativa
A40: ENOE | B40: Encuesta Nacional de Ocupación y Empleo Trimestral
A41: IED | B41: Inversión Extranjera Directa hacia México por Entidad Federativa
A42: DENUE | B42: Directorio Estadístico Nacional de Unidades Económicas
A43: CET | B43: Compendio Estadístico del Turismo en México
...

Sheet Detalle
A1: Variable | B1: Etiqueta | C1: Tipo | D1: Periodicidad | E1: Fecha | F1: Periodo actualizado | G1: Fuente
A2: Producto Interno Bruto por Entidad Federativa | B2: PIBE (2024) | C2: Cifras Revisadas | D2: Anual | E2: 46209.25 | F2: 2024 | G2: INEGI
A3: Producto Interno Bruto por Entidad Federativa | B3: PIBE (2025) | C3: Cifras Preliminares | D3: Anual | E3: 46363.25 | F3: 2025 | G3: INEGI
A4: Exportaciones por Entidad Federativa | B4: EEF (4T2025) | C4: Cifras Preliminares | D4: Trimestral | E4: 46112.25 | F4: 4T2025 | G4: INEGI
A5: Exportaciones por Entidad Federativa | B5: EEF (1T2026) | C5: Cifras Preliminares | D5: Trimestral | E5: 46203.25 | F5: 1T2026 | G5: INEGI
A6: Exportaciones por Entidad Federativa | B6: EEF (2T2026) | C6: Cifras Preliminares | D6: Trimestral | E6: 46295.25 | F6: 2T2026 | G6: INEGI
A7: Exportaciones por Entidad Federativa | B7: EEF (3T2026) | C7: Cifras Preliminares | D7: Trimestral | E7: 46379.25 | F7: 3T2026 | G7: INEGI
A8: Encuesta Nacional de Ocupación y Empleo | B8: ENOE (4T2025) | C8: Cifras Definitivas | D8: Trimestral | E8: 46077.25 | F8: 4T2025 | G8: INEGI
A9: Encuesta Nacional de Ocupación y Empleo | B9: ENOE (1T2026) | C9: Cifras Definitivas | D9: Trimestral | E9: 46168.25 | F9: 1T2026 | G9: INEGI
A10: Encuesta Nacional de Ocupación y Empleo | B10: ENOE (2T2026) | C10: Cifras Definitivas | D10: Trimestral | E10: 46259.25 | F10: 2T2026 | G10: INEGI
A11: Encuesta Nacional de Ocupación y Empleo | B11: ENOE (3T2026) | C11: Cifras Definitivas | D11: Trimestral | E11: 46351.25 | F11: 3T2026 | G11: INEGI
A12: Inversión Extranjera Directa hacia México por Entidad | B12: IED (4T2025) | C12: Cifras Revisadas | D12: Trimestral | E12: 46100.25 | F12: 4T2025 | G12: SE
A13: Inversión Extranjera Directa hacia México por Entidad | B13: IED (1T2026) | C13: Cifras Revisadas | D13: Trimestral | F13: 1T2026 | G13: SE
A14: Inversión Extranjera Directa hacia México por Entidad | B14: IED (2T2026) | C14: Cifras Revisadas | D14: Trimestral | F14: 2T2026 | G14: SE
A15: Inversión Extranjera Directa hacia México por Entidad | B15: IED (3T2026) | C15: Cifras Revisadas | D15: Trimestral | F15: 3T2026 | G15: SE
A16: DENUE | B16: DENUE (2025) | C16: Cifras Definitivas | D16: Anual | E16: 46162.25 | F16: 2025 | G16: INEGI
A17: DENUE | B17: DENUE (2025) | C17: Cifras Definitivas | D17: Anual | E17: 46351.25 | F17: 2025 | G17: INEGI
A18: Recepción de Turistas | B18: CET (2025) | C18: Cifras Revisadas | D18: Anual | E18: 46341.375 | F18: 2025 | G18: DATATUR
A19: Educación Superior | B19: ANUIES (2025-2026) | C19: Cifras Revisadas | D19: Anual | E19: 46341.375 | F19: 2025-2026 | G19: ANUIES
A20: Indicadores de Competitividad | B20: IMCO (2026) | C20: - | D20: Anual | E20: 46188.375 | F20: 2026 | G20: IMCO
A21: Puestos de trabajo y salario por entidad | B21: IMSS (mensual 2026) | C21: - | D21: Mensual | E21: antes del 9 de cada mes | F21: 2026 | G21: IMSS
A22: Productividad Laboral: Producción Bruta/Personal Ocupado | B22: PL (Censos Económicos) | C22: - | D22: Anual | E22: Sin actualización programada | G22: INEGI
A23: Censos Poblacionales (2020) | B23: CP | C23: - | D23: Anual | E23: Sin actualización programada | G23: CONAPO
A25: Sin actualización programada este año.

Sheet Pendientes
A1: Variable | B1: Etiqueta | C1: Tipo | D1: Periodicidad | E1: Periodo actualizado | F1: Fuente
A2: Inversión Extranjera Directa hacia México por Entidad | B2: IED (1T2026) | C2: Cifras Revisadas | D2: Trimestral | E2: 1T2026 | F2: SE
A3: Inversión Extranjera Directa hacia México por Entidad | B3: IED (2T2026) | C3: Cifras Revisadas | D3: Trimestral | E3: 2T2026 | F3: SE
A4: Inversión Extranjera Directa hacia México por Entidad | B4: IED (3T2026) | C4: Cifras Revisadas | D4: Trimestral | E4: 3T2026 | F4: SE
A5: Productividad Laboral: Producción Bruta/Personal Ocupado | B5: PL (Censos Económicos) | C5: - | D5: Anual | E5: Sin actualización programada | F5: INEGI
A6: Censos Poblacionales (2020) | B6: CP | C6: - | D6: Anual | E6: Sin actualización programada | F6: INEGI
A8: Sin actualización programada este año.
